Workbook

Sheet Summary
F1: Updated on | G1: 46218
A2: Engg VP | B2: Engg Director | C2: Component | D2: Count of Sub-component
A3: Justin Hou | B3: Koyeli Dasgupta | C3: L&D | D3: 1 | F3: Confluence
A4: Keith Wiseman | B4: Vaibhav Saini | C4: APC | D4: 3 | F4: https://tekion.atlassian.net/wiki/spaces/TW/pages/4454875476/JIRA+Component+Sub-Component+Cleanup
C5: ApplicationPlatforms | D5: 10
B6: Bobby Alexander | C6: OnboardingPlatforms | D6: 9
C7: ZEBRA | D7: 3
A8: Kunal Bhattacharya | B8: Kapileshwar Punna | C8: Security | D8: 5
A9: Marc Stillman | B9: Gaurav Sharma | C9: VOC | D9: 1
A10: Raghu Edalur | B10: Jawahar Prasad | C10: ORBIT | D10: 7
C11: T1Platform | D11: 3
B12: Parul Jain | C12: HorizontalPlatforms | D12: 12
B13: Raghu Edalur | C13: Architecture | D13: 1
A14: Santosh Golecha | B14: Aditya Kolli | C14: AEPlatform | D14: 12
C15: AMC | D15: 1
B16: Ankur Agarwal | C16: DR_Honda | D16: 16
C17: DR_Hyundai | D17: 4
C18: Fleet_Honda | D18: 10
C19: IOT | D19: 4
B20: Manoj Kansal | C20: DR_GM | D20: 37
B21: Santosh Golecha | C21: AECIntegration | D21: 3
C22: DR_Ford | D22: 3
A23: Sanyam Agrawal | B23: Ambuj Mehra | C23: PayTek | D23: 3
B24: Anirudh Agarwal | C24: Parts | D24: 18
B25: Fahad Tasleem | C25: Accounting | D25: 8
C26: Cashiering | D26: 1
C27: eSign_Platform | D27: 1
C28: Payroll | D28: 4
B29: Prashant Gupta, Vraj Solanki | C29: Service | D29: 15
A30: Satish Sallakonda | B30: Anvesh Aileni | C30: Analytics | D30: 5
B31: Bob Wagoner | C31: Data_Services | D31: 5
B32: Prakash Mohan | C32: ARCIntegration | D32: 4
B33: Satish Sallakonda | C33: AI_Core | D33: 12
C34: APEX | D34: 10
B35: Ajay Rao | C35: DataPlatform | D35: 9
B36: Satyajeet Singh | C36: AIE_Core | D36: 12
C37: AIE_Platform | D37: 10
A38: Srin Tangirala | B38: Arul Jothi | C38: DataEngg | D38: 3
B39: Srin Tangirala | C39: Professional_Services | D39: 1
A40: Teza Mukkavilli | B40: Ramesh Sarabu | C40: TOC_Horizontal | D40: 7
...

Sheet Unique Components
A1: Component
A2: CRM | B2: Ved Singh
A3: Core | B3: Uma Shanker
A4: RuleEngine | B4: Uma Shanker
A5: Campaign | B5: Ved Singh
A6: Bootstrapping | B6: Uma Shanker
A7: ARCIntegration | B7: Satish
A8: CMS | B8: Satish
A9: Galaxy | B9: Ved Singh
A10: Retail | B10: Ved Singh
A11: ML | B11: Satish
A12: Accounting | B12: Sanyam
A13: Payroll | B13: Sanyam
... A20: Platform | B20: Uma Shanker
A21: PerformanceEngg
A22: APC | B22: Uma Shanker
A23: DataPlatform | B23: Satish
A24: AECPlatform | B24: Ved Singh
A25: Analytics | B25: Satish
A26: Insights
A27: TAP | B27: Teza
A28: DataEngg
A29: Infra | B29: Viraj
A30: IOT/Hardware
A31: DR_GM
A32: DR_Ford
A33: AECIntegration
A34: L&D
A35: DR_Honda
A36: DealerLaunchAutomation
A37: FnI
A38: Architecture
A39: AIBDC
A40: DR_Hyundai
A41: MLPlatform
... A45: HR_Team

Sheet Projects
A1: Unique Projects | B1: JIRA Key | C1: Phase | D1: Capacity per Release | F1: Phase | G1: Starts
A2: Accounting & Payroll | B2: ACCT | C2: GA | F2: Pilot v1 | G2: July sprint
A3: AEC Platform | B3: AECP | C3: GA | F3: Pilot v2 | G3: Aug sprint
A4: Data & Analytics | B4: DATA | C4: GA | F4: GA | G4: Oct sprint
A5: APC | B5: APC | C5: GA
A6: Integration | B6: INT | C6: GA
A7: CRM | B7: CRM | C7: Pilot v1 | D7: 560
A8: PayTek | B8: PYTK | C8: Pilot v1 | D8: 170
A9: Core | B9: CORE | C9: GA
A10: Migration & Conversion | B10: MICV | C10: GA
A11: FnI | B11: FNI | C11: Pilot v1 | D11: 216
A12: Galaxy | B12: GAL | C12: Pilot v1 | D12: 120
A13: Mobile | B13: MOB | C13: GA
A14: Parts | B14: PART | C14: GA
A15: Platform | B15: PLTF | C15: GA
A16: Retail | B16: RETL | C16: Pilot v2
A17: Service | B17: SERV | C17: GA
A18: Hyundai | B18: HYUN | C18: Pilot v2
A19: AIBDC | B19: AIB | C19: Pilot v1
A20: Reliability | B20: RELB | C20: Pilot v2
A26: Component | B26: Engg Director / Leader | C26: Project | D26: Key | E26: Remarks
A27: Accounting | B27: Fahad Tasleem | C27: Accounting & Payroll | D27: ACCT
A28: AECIntegration | B28: Santosh Golecha | E28: To be discussed later
A29: AECPlatform | B29: Jawahar Prasad | C29: AEC Platform | D29: AECP
A30: Analytics | B30: Venkateswarlu Yerramalli | C30: Data & Analytics | D30: DATA
A31: APC | B31: Vaibhav Saini | C31: APC | D31: APC
A32: ARCIntegration | B32: Prakash Mohan | C32: Integration | D32: INT
A33: Campaign | B33: Abhishek Agarwala | C33: CRM | D33: CRM | E33: Merged under CRM
A34: Cashiering | B34: Prashant Gupta | C34: PayTek | D34: PYTK | E34: Needs discussion as Engg team reports to Prashant Gupta
A35: CMS | B35: Satish Sallakonda | C35: Data & Analytics | D35: DATA
A36: Core | B36: Surya Narayanan | C36: Core | D36: CORE
A37: CRM | B37: Abhishek Agarwala | C37: CRM | D37: CRM
A38: DataEngg | B38: Arul Jothi | C38: Migration & Conversion | D38: MICV
A39: DataPlatform | B39: Raghu Ram Vengalil | C39: Data & Analytics | D39: DATA
A40: DealerLaunchAutomation | B40: Surya Narayanan | E40: To be discussed later
A41: DR_Ford | B41: Santosh Golecha | E41: To be discussed later
A42: DR_GM | B42: Santosh Golecha | E42: To be discussed later
A43: DR_Honda | B43: Santosh Golecha | E43: To be discussed later
A44: eSign_Platform | B44: Prashant Gupta | C44: FnI | D44: FNI | E44: Needs discussion as Engg team reports to Prashant Gupta
A45: FnI | B45: Abhishek Agarwala | C45: FnI | D45: FNI
...

Sheet JIRA
A1: Component JIRA mapping | J1: Sub-component JIRA mapping
A3: Project | B3: Issue type | C3: Required | D3: Create Screen | E3: View Screen | F3: Edit Screen | G3: Mandatory | H3: Remarks | J3: Project | K3: Issue type | L3: Required | M3: Create Screen | N3: View Screen | O3: Edit Screen | P3: Mandatory | Q3: Remarks
A4: ENG | B4: Story | C4: Y | D4: Y | E4: Y | F4: Y | G4: Y | J4: ENG | K4: Story | L4: Y | M4: Y | N4: Y | O4: Y | P4: Y
A5: ENG | B5: Bug | C5: Y | D5: Y | E5: Y | F5: Y | G5: Y | J5: ENG | K5: Bug | L5: Y | M5: Y | N5: Y | O5: Y | P5: N | Q5: Transition
A6: ENG | B6: Epic | C6: Y | D6: Y | E6: Y | F6: Y | G6: Y | J6: ENG | K6: Epic | L6: Y | M6: Y | N6: Y | O6: Y | P6: N
A7: ENG | B7: Feature | C7: Y | D7: Y | E7: Y | F7: Y | G7: Y | J7: ENG | K7: Feature | L7: N | M7: N | N7: N | O7: N | P7: N
A8: ENG | B8: HFR | C8: Y | D8: Y | E8: Y | F8: Y | G8: Y | J8: ENG | K8: HFR | L8: N | M8: N | N8: N | O8: N | P8: N
A9: ENG | B9: TAP Ticket | C9: Y | D9: Y | E9: Y | F9: Y | G9: Y | J9: ENG | K9: TAP Ticket | L9: Y | M9: Y | N9: Y | O9: Y | P9: N | Q9: Transition
A10: ENG | B10: Task | C10: Y | D10: Y | E10: Y | F10: Y | G10: N | H10: TBD | J10: ENG | K10: Task | L10: Y | M10: Y | N10: Y | O10: Y | P10: N | Q10: TBD
A11: ENG | B11: Sub-task | C11: Y | D11: Y | E11: Y | F11: Y | G11: N | H11: TBD | J11: ENG | K11: Sub-task | L11: Y | M11: Y | N11: Y | O11: Y | P11: N | Q11: TBD
A12: ENG | B12: TCC Incident | C12: Y | D12: Y | E12: Y | F12: Y | G12: N | H12: Transition | J12: ENG | K12: TCC Incident | L12: Y | M12: Y | N12: Y | O12: Y | P12: N | Q12: Transition
A13: PM | B13: Epic | C13: Y | D13: Y | E13: Y | F13: Y | G13: Y | J13: PM | K13: Epic | L13: Y | M13: Y | N13: Y | O13: Y | P13: N
A14: PM | B14: Feature | C14: Y | D14: Y | E14: Y | F14: Y | G14: Y | J14: PM | K14: Feature | L14: N | M14: N | N14: N | O14: N | P14: N
A15: PM | B15: Initiative | C15: N | D15: N | E15: N | F15: N | G15: N | J15: PM | K15: Initiative | L15: N | M15: N | N15: N | O15: N | P15: N
A16: PM | B16: SCR | C16: Y | D16: Y | E16: Y | F16: N | G16: Y | J16: PM | K16: SCR | L16: N | M16: N | N16: N | O16: N | P16: N

Sheet Component Masterlist v2
A1: Component | B1: Sub-component | C1: Sub-Component Owner - EM | D1: Sr. Engg Manager | E1: Engg Director | F1: Sr. Engg Director | G1: Engg VP | H1: PM | I1: Manager, PM | J1: Sr. Manager, PM | K1: Product Director | L1: Sr. Product Director | M1: Product VP | N1: SDET | O1: Scrum Team | P1: PDLC Project Key | Q1: TPM Assigned | R1: Old Sub-component Name
A2: CRM | B2: CRM-Lead_Assignment | C2: Nitesh Khadanga | E2: Arun Gangadhar | G2: Ved Singh | H2: Shivam Arora | I2: Subhash Mohan | K2: Rashmi Prakash | L2: Gaurav Gupta | M2: Satyavrat Mudgil | N2: Komala | O2: {=IFERROR( INDEX('Scrum Teams'!B$2:B$1010, MATCH(1, (B2='Scrum Teams'!F$2:F$1010) + (B2='Scrum Teams'!G$2:G$1010) + (B2='Scrum Teams'!H$2:H$1010) + (B2='Scrum Teams'!I$2:I$1010) + (B2='Scrum Teams'!J$2:J$1010) + (B2='Scrum Teams'!K$2:K$1010) + (B2='Scrum Teams'!L$2:L$1010) + (B2='Scrum Teams'!M$2:M$1010) + (B2='Scrum Teams'!N$2:N$1010) + (B2='Scrum Teams'!O$2:O$1010) + (B2='Scrum Teams'!P$2:P$1010) + (B2='Scrum Teams'!Q$2:Q$1010), 0) ), "Not found" )} -> Wolverine | P2: CRM | Q2: Srividya Mandalapu
A3: CRM | B3: CRM-Leads | C3: Nitesh Khadanga | E3: Arun Gangadhar | G3: Ved Singh | H3: Jitendra Rahangdale | I3: Subhash Mohan | K3: Rashmi Prakash | L3: Gaurav Gupta | M3: Satyavrat Mudgil | N3: Komala | O3: {=IFERROR( INDEX('Scrum Teams'!B$2:B$1010, MATCH(1, (B3='Scrum Teams'!F$2:F$1010) + (B3='Scrum Teams'!G$2:G$1010) + (B3='Scrum Teams'!H$2:H$1010) + (B3='Scrum Teams'!I$2:I$1010) + (B3='Scrum Teams'!J$2:J$1010) + (B3='Scrum Teams'!K$2:K$1010) + (B3='Scrum Teams'!L$2:L$1010) + (B3='Scrum Teams'!M$2:M$1010) + (B3='Scrum Teams'!N$2:N$1010) + (B3='Scrum Teams'!O$2:O$1010) + (B3='Scrum Teams'!P$2:P$1010) + (B3='Scrum Teams'!Q$2:Q$1010), 0) ), "Not found" )} -> Wolverine | P3: CRM | Q3: Srividya Mandalapu
A4: CRM | B4: CRM-Migration | C4: Mani T | E4: Arun Gangadhar | G4: Ved Singh | H4: Subhash Mohan | K4: Rashmi Prakash | L4: Gaurav Gupta | M4: Satyavrat Mudgil | N4: Komala | O4: {=IFERROR( INDEX('Scrum Teams'!B$2:B$1010, MATCH(1, (B4='Scrum Teams'!F$2:F$1010) + (B4='Scrum Teams'!G$2:G$1010) + (B4='Scrum Teams'!H$2:H$1010) + (B4='Scrum Teams'!I$2:I$1010) + (B4='Scrum Teams'!J$2:J$1010) + (B4='Scrum Teams'!K$2:K$1010) + (B4='Scrum Teams'!L$2:L$1010) + (B4='Scrum Teams'!M$2:M$1010) + (B4='Scrum Teams'!N$2:N$1010) + (B4='Scrum Teams'!O$2:O$1010) + (B4='Scrum Teams'!P$2:P$1010) + (B4='Scrum Teams'!Q$2:Q$1010), 0) ), "Not found" )} -> Gambit | P4: CRM | Q4: Srividya Mandalapu
A5: CRM | B5: CRM-Mobile | C5: Mani T | E5: Arun Gangadhar | G5: Ved Singh | H5: Shivam Arora | I5: Subhash Mohan | K5: Rashmi Prakash | L5: Gaurav Gupta | M5: Satyavrat Mudgil | N5: Komala | O5: {=IFERROR( INDEX('Scrum Teams'!B$2:B$1010, MATCH(1, (B5='Scrum Teams'!F$2:F$1010) + (B5='Scrum Teams'!G$2:G$1010) + (B5='Scrum Teams'!H$2:H$1010) + (B5='Scrum Teams'!I$2:I$1010) + (B5='Scrum Teams'!J$2:J$1010) + (B5='Scrum Teams'!K$2:K$1010) + (B5='Scrum Teams'!L$2:L$1010) + (B5='Scrum Teams'!M$2:M$1010) + (B5='Scrum Teams'!N$2:N$1010) + (B5='Scrum Teams'!O$2:O$1010) + (B5='Scrum Teams'!P$2:P$1010) + (B5='Scrum Teams'!Q$2:Q$1010), 0) ), "Not found" )} -> Mystique | P5: CRM | Q5: Srividya Mandalapu
A6: CRM | B6: CRM-Task | C6: Jyothi Vejju | E6: Arun Gangadhar | G6: Ved Singh | H6: Jitendra Rahangdale | I6: Subhash Mohan | K6: Rashmi Prakash | L6: Gaurav Gupta | M6: Satyavrat Mudgil | N6: Komala | O6: {=IFERROR( INDEX('Scrum Teams'!B$2:B$1010, MATCH(1, (B6='Scrum Teams'!F$2:F$1010) + (B6='Scrum Teams'!G$2:G$1010) + (B6='Scrum Teams'!H$2:H$1010) + (B6='Scrum Teams'!I$2:I$1010) + (B6='Scrum Teams'!J$2:J$1010) + (B6='Scrum Teams'!K$2:K$1010) + (B6='Scrum Teams'!L$2:L$1010) + (B6='Scrum Teams'!M$2:M$1010) + (B6='Scrum Teams'!N$2:N$1010) + (B6='Scrum Teams'!O$2:O$1010) + (B6='Scrum Teams'!P$2:P$1010) + (B6='Scrum Teams'!Q$2:Q$1010), 0) ), "Not found" )} -> Storm | P6: CRM | Q6: Srividya Mandalapu
A7: CRM | B7: CRM-Appointment | C7: Jyothi Vejju | E7: Arun Gangadhar | G7: Ved Singh | H7: Jitendra Rahangdale | I7: Subhash Mohan | K7: Rashmi Prakash | L7: Gaurav Gupta | M7: Satyavrat Mudgil | N7: Komala | O7: {=IFERROR( INDEX('Scrum Teams'!B$2:B$1010, MATCH(1, (B7='Scrum Teams'!F$2:F$1010) + (B7='Scrum Teams'!G$2:G$1010) + (B7='Scrum Teams'!H$2:H$1010) + (B7='Scrum Teams'!I$2:I$1010) + (B7='Scrum Teams'!J$2:J$1010) + (B7='Scrum Teams'!K$2:K$1010) + (B7='Scrum Teams'!L$2:L$1010) + (B7='Scrum Teams'!M$2:M$1010) + (B7='Scrum Teams'!N$2:N$1010) + (B7='Scrum Teams'!O$2:O$1010) + (B7='Scrum Teams'!P$2:P$1010) + (B7='Scrum Teams'!Q$2:Q$1010), 0) ), "Not found" )} -> Storm | P7: CRM | Q7: Srividya Mandalapu
A8: CRM | B8: CRM-Reports | C8: Nawaz Baba | E8: Arun Gangadhar | G8: Ved Singh | H8: Jitendra Rahangdale | I8: Subhash Mohan | K8: Rashmi Prakash | L8: Gaurav Gupta | M8: Satyavrat Mudgil | N8: Komala | O8: {=IFERROR( INDEX('Scrum Teams'!B$2:B$1010, MATCH(1, (B8='Scrum Teams'!F$2:F$1010) + (B8='Scrum Teams'!G$2:G$1010) + (B8='Scrum Teams'!H$2:H$1010) + (B8='Scrum Teams'!I$2:I$1010) + (B8='Scrum Teams'!J$2:J$1010) + (B8='Scrum Teams'!K$2:K$1010) + (B8='Scrum Teams'!L$2:L$1010) + (B8='Scrum Teams'!M$2:M$1010) + (B8='Scrum Teams'!N$2:N$1010) + (B8='Scrum Teams'!O$2:O$1010) + (B8='Scrum Teams'!P$2:P$1010) + (B8='Scrum Teams'!Q$2:Q$1010), 0) ), "Not found" )} -> Bishop | P8: CRM | Q8: Srividya Mandalapu
A9: CRM | B9: CRM-Dashboards | C9: Nawaz Baba | E9: Arun Gangadhar | G9: Ved Singh | H9: Jitendra Rahangdale | I9: Subhash Mohan | K9: Rashmi Prakash | L9: Gaurav Gupta | M9: Satyavrat Mudgil | N9: Komala | O9: {=IFERROR( INDEX('Scrum Teams'!B$2:B$1010, MATCH(1, (B9='Scrum Teams'!F$2:F$1010) + (B9='Scrum Teams'!G$2:G$1010) + (B9='Scrum Teams'!H$2:H$1010) + (B9='Scrum Teams'!I$2:I$1010) + (B9='Scrum Teams'!J$2:J$1010) + (B9='Scrum Teams'!K$2:K$1010) + (B9='Scrum Teams'!L$2:L$1010) + (B9='Scrum Teams'!M$2:M$1010) + (B9='Scrum Teams'!N$2:N$1010) + (B9='Scrum Teams'!O$2:O$1010) + (B9='Scrum Teams'!P$2:P$1010) + (B9='Scrum Teams'!Q$2:Q$1010), 0) ), "Not found" )} -> Bishop | P9: CRM | Q9: Srividya Mandalapu
A10: CRM | B10: CRM-AI | C10: Mani T | E10: Arun Gangadhar | G10: Ved Singh | H10: Shivam Arora | I10: Subhash Mohan | K10: Rashmi Prakash | L10: Gaurav Gupta | M10: Satyavrat Mudgil | N10: Komala | O10: {=IFERROR( INDEX('Scrum Teams'!B$2:B$1010, MATCH(1, (B10='Scrum Teams'!F$2:F$1010) + (B10='Scrum Teams'!G$2:G$1010) + (B10='Scrum Teams'!H$2:H$1010) + (B10='Scrum Teams'!I$2:I$1010) + (B10='Scrum Teams'!J$2:J$1010) + (B10='Scrum Teams'!K$2:K$1010) + (B10='Scrum Teams'!L$2:L$1010) + (B10='Scrum Teams'!M$2:M$1010) + (B10='Scrum Teams'!N$2:N$1010) + (B10='Scrum Teams'!O$2:O$1010) + (B10='Scrum Teams'!P$2:P$1010) + (B10='Scrum Teams'!Q$2:Q$1010), 0) ), "Not found" )} -> Mystique | P10: CRM | Q10: Srividya Mandalapu
A11: CRM | B11: CRM-Retail_Mobile | C11: Mani T | E11: Arun Gangadhar | G11: Ved Singh | H11: Palash Sanjay Kotgirwar | I11: Hardik Paharia | J11: Hardik Paharia | K11: Gaurav Gupta | L11: Gaurav Gupta | M11: Satyavrat Mudgil | N11: Komala | O11: {=IFERROR( INDEX('Scrum Teams'!B$2:B$1010, MATCH(1, (B11='Scrum Teams'!F$2:F$1010) + (B11='Scrum Teams'!G$2:G$1010) + (B11='Scrum Teams'!H$2:H$1010) + (B11='Scrum Teams'!I$2:I$1010) + (B11='Scrum Teams'!J$2:J$1010) + (B11='Scrum Teams'!K$2:K$1010) + (B11='Scrum Teams'!L$2:L$1010) + (B11='Scrum Teams'!M$2:M$1010) + (B11='Scrum Teams'!N$2:N$1010) + (B11='Scrum Teams'!O$2:O$1010) + (B11='Scrum Teams'!P$2:P$1010) + (B11='Scrum Teams'!Q$2:Q$1010), 0) ), "Not found" )} -> Mystique | P11: CRM | Q11: Srividya Mandalapu
A12: CRM | B12: CRM-Sales_AI | C12: Mani T | E12: Arun Gangadhar | G12: Ved Singh | H12: Preetiranjan Pradhan | K12: Rashmi Prakash | L12: Gaurav Gupta | M12: Satyavrat Mudgil | N12: Komala | O12: {=IFERROR( INDEX('Scrum Teams'!B$2:B$1010, MATCH(1, (B12='Scrum Teams'!F$2:F$1010) + (B12='Scrum Teams'!G$2:G$1010) + (B12='Scrum Teams'!H$2:H$1010) + (B12='Scrum Teams'!I$2:I$1010) + (B12='Scrum Teams'!J$2:J$1010) + (B12='Scrum Teams'!K$2:K$1010) + (B12='Scrum Teams'!L$2:L$1010) + (B12='Scrum Teams'!M$2:M$1010) + (B12='Scrum Teams'!N$2:N$1010) + (B12='Scrum Teams'!O$2:O$1010) + (B12='Scrum Teams'!P$2:P$1010) + (B12='Scrum Teams'!Q$2:Q$1010), 0) ), "Not found" )} -> Mystique | P12: CRM | Q12: Srividya Mandalapu
A13: CRM | B13: CRM-Pro | C13: Mani T | E13: Arun Gangadhar | G13: Ved Singh | H13: Preetiranjan Pradhan | K13: Rashmi Prakash | L13: Gaurav Gupta | M13: Satyavrat Mudgil | N13: Komala | O13: {=IFERROR( INDEX('Scrum Teams'!B$2:B$1010, MATCH(1, (B13='Scrum Teams'!F$2:F$1010) + (B13='Scrum Teams'!G$2:G$1010) + (B13='Scrum Teams'!H$2:H$1010) + (B13='Scrum Teams'!I$2:I$1010) + (B13='Scrum Teams'!J$2:J$1010) + (B13='Scrum Teams'!K$2:K$1010) + (B13='Scrum Teams'!L$2:L$1010) + (B13='Scrum Teams'!M$2:M$1010) + (B13='Scrum Teams'!N$2:N$1010) + (B13='Scrum Teams'!O$2:O$1010) + (B13='Scrum Teams'!P$2:P$1010) + (B13='Scrum Teams'!Q$2:Q$1010), 0) ), "Not found" )} -> Mystique | P13: CRM | Q13: Srividya Mandalapu
A14: CRM | B14: CRM-Compliance | C14: Jyothi Vejju | E14: Arun Gangadhar | G14: Ved Singh | H14: Piyush Kumar | I14: Avin Jain | K14: Ashish Kalya | M14: Shiva Somasundaram | N14: Komala | O14: {=IFERROR( INDEX('Scrum Teams'!B$2:B$1010, MATCH(1, (B14='Scrum Teams'!F$2:F$1010) + (B14='Scrum Teams'!G$2:G$1010) + (B14='Scrum Teams'!H$2:H$1010) + (B14='Scrum Teams'!I$2:I$1010) + (B14='Scrum Teams'!J$2:J$1010) + (B14='Scrum Teams'!K$2:K$1010) + (B14='Scrum Teams'!L$2:L$1010) + (B14='Scrum Teams'!M$2:M$1010) + (B14='Scrum Teams'!N$2:N$1010) + (B14='Scrum Teams'!O$2:O$1010) + (B14='Scrum Teams'!P$2:P$1010) + (B14='Scrum Teams'!Q$2:Q$1010), 0) ), "Not found" )} -> Storm | P14: CRM | Q14: Srividya Mandalapu | R14: CRM-Communication_Preferences
A15: CRM | B15: CRM-CDM | C15: Siddharth Gaur | E15: Arun Gangadhar | G15: Ved Singh | P15: CRM | Q15: Srividya Mandalapu
A16: CRM | B16: CRM-CMS | C16: Siddharth Gaur | E16: Arun Gangadhar | G16: Ved Singh | P16: CRM | Q16: Srividya Mandalapu
A17: Campaign | B17: Campaign-Core | C17: Nawaz Baba | E17: Arun Gangadhar | G17: Ved Singh | H17: Uday Jumle | K17: Rashmi Prakash | L17: Gaurav Gupta | M17: Satyavrat Mudgil | N17: Komala | O17: {=IFERROR( INDEX('Scrum Teams'!B$2:B$1010, MATCH(1, (B17='Scrum Teams'!F$2:F$1010) + (B17='Scrum Teams'!G$2:G$1010) + (B17='Scrum Teams'!H$2:H$1010) + (B17='Scrum Teams'!I$2:I$1010) + (B17='Scrum Teams'!J$2:J$1010) + (B17='Scrum Teams'!K$2:K$1010) + (B17='Scrum Teams'!L$2:L$1010) + (B17='Scrum Teams'!M$2:M$1010) + (B17='Scrum Teams'!N$2:N$1010) + (B17='Scrum Teams'!O$2:O$1010) + (B17='Scrum Teams'!P$2:P$1010) + (B17='Scrum Teams'!Q$2:Q$1010), 0) ), "Not found" )} -> Bishop | P17: CRM | Q17: Srividya Mandalapu
A18: Communication | B18: Communication-Calling | C18: Vikash kumar | E18: Ketan Dikshit | G18: Ved Singh | H18: Jutla Manaswini | I18: Avin Jain | K18: Ashish Kalya | M18: Shiva Somasundaram | O18: {=IFERROR( INDEX('Scrum Teams'!B$2:B$1010, MATCH(1, (B18='Scrum Teams'!F$2:F$1010) + (B18='Scrum Teams'!G$2:G$1010) + (B18='Scrum Teams'!H$2:H$1010) + (B18='Scrum Teams'!I$2:I$1010) + (B18='Scrum Teams'!J$2:J$1010) + (B18='Scrum Teams'!K$2:K$1010) + (B18='Scrum Teams'!L$2:L$1010) + (B18='Scrum Teams'!M$2:M$1010) + (B18='Scrum Teams'!N$2:N$1010) + (B18='Scrum Teams'!O$2:O$1010) + (B18='Scrum Teams'!P$2:P$1010) + (B18='Scrum Teams'!Q$2:Q$1010), 0) ), "Not found" )} -> Not found | P18: COMM | Q18: Srividya Mandalapu | R18: CRM-Communication
A19: Communication | B19: Communication-Texting | E19: Ketan Dikshit | G19: Ved Singh | H19: Piyush Kumar | I19: Avin Jain | K19: Ashish Kalya | M19: Shiva Somasundaram | O19: {=IFERROR( INDEX('Scrum Teams'!B$2:B$1010, MATCH(1, (B19='Scrum Teams'!F$2:F$1010) + (B19='Scrum Teams'!G$2:G$1010) + (B19='Scrum Teams'!H$2:H$1010) + (B19='Scrum Teams'!I$2:I$1010) + (B19='Scrum Teams'!J$2:J$1010) + (B19='Scrum Teams'!K$2:K$1010) + (B19='Scrum Teams'!L$2:L$1010) + (B19='Scrum Teams'!M$2:M$1010) + (B19='Scrum Teams'!N$2:N$1010) + (B19='Scrum Teams'!O$2:O$1010) + (B19='Scrum Teams'!P$2:P$1010) + (B19='Scrum Teams'!Q$2:Q$1010), 0) ), "Not found" )} -> Not found | P19: COMM | Q19: Srividya Mandalapu
A20: Communication | B20: Communication-Email | E20: Ketan Dikshit | G20: Ved Singh | H20: Abhinav Wagadre | K20: Ashish Kalya | M20: Shiva Somasundaram | O20: {=IFERROR( INDEX('Scrum Teams'!B$2:B$1010, MATCH(1, (B20='Scrum Teams'!F$2:F$1010) + (B20='Scrum Teams'!G$2:G$1010) + (B20='Scrum Teams'!H$2:H$1010) + (B20='Scrum Teams'!I$2:I$1010) + (B20='Scrum Teams'!J$2:J$1010) + (B20='Scrum Teams'!K$2:K$1010) + (B20='Scrum Teams'!L$2:L$1010) + (B20='Scrum Teams'!M$2:M$1010) + (B20='Scrum Teams'!N$2:N$1010) + (B20='Scrum Teams'!O$2:O$1010) + (B20='Scrum Teams'!P$2:P$1010) + (B20='Scrum Teams'!Q$2:Q$1010), 0) ), "Not found" )} -> Not found | P20: COMM | Q20: Srividya Mandalapu
A21: Communication | B21: Communication-Live_Chat | E21: Ketan Dikshit | G21: Ved Singh | H21: Abhinav Wagadre | K21: Ashish Kalya | M21: Shiva Somasundaram | O21: {=IFERROR( INDEX('Scrum Teams'!B$2:B$1010, MATCH(1, (B21='Scrum Teams'!F$2:F$1010) + (B21='Scrum Teams'!G$2:G$1010) + (B21='Scrum Teams'!H$2:H$1010) + (B21='Scrum Teams'!I$2:I$1010) + (B21='Scrum Teams'!J$2:J$1010) + (B21='Scrum Teams'!K$2:K$1010) + (B21='Scrum Teams'!L$2:L$1010) + (B21='Scrum Teams'!M$2:M$1010) + (B21='Scrum Teams'!N$2:N$1010) + (B21='Scrum Teams'!O$2:O$1010) + (B21='Scrum Teams'!P$2:P$1010) + (B21='Scrum Teams'!Q$2:Q$1010), 0) ), "Not found" )} -> Not found | P21: COMM | Q21: Srividya Mandalapu
A22: Communication | B22: Communication-Unified_Platform | C22: Vikash kumar | E22: Ketan Dikshit | G22: Ved Singh | H22: Jutla Manaswini | I22: Avin Jain | K22: Ashish Kalya | M22: Shiva Somasundaram | O22: {=IFERROR( INDEX('Scrum Teams'!B$2:B$1010, MATCH(1, (B22='Scrum Teams'!F$2:F$1010) + (B22='Scrum Teams'!G$2:G$1010) + (B22='Scrum Teams'!H$2:H$1010) + (B22='Scrum Teams'!I$2:I$1010) + (B22='Scrum Teams'!J$2:J$1010) + (B22='Scrum Teams'!K$2:K$1010) + (B22='Scrum Teams'!L$2:L$1010) + (B22='Scrum Teams'!M$2:M$1010) + (B22='Scrum Teams'!N$2:N$1010) + (B22='Scrum Teams'!O$2:O$1010) + (B22='Scrum Teams'!P$2:P$1010) + (B22='Scrum Teams'!Q$2:Q$1010), 0) ), "Not found" )} -> Not found | P22: COMM | Q22: Srividya Mandalapu | R22: Communication-Platform
A23: ApplicationPlatforms | B23: AP-Compliance | C23: Venkatesh naik | E23: Vaibhav Saini | F23: Surya Narayanan | G23: Keith Wiseman | H23: Lohit Reddy | I23: Vamsee Krishna Mullapudi | J23: Vamsee Krishna Mullapudi | K23: Vijayakumar B | M23: Shiva Somasundaram | N23: Shashi Kumar | O23: {=IFERROR( INDEX('Scrum Teams'!B$2:B$1010, MATCH(1, (B23='Scrum Teams'!F$2:F$1010) + (B23='Scrum Teams'!G$2:G$1010) + (B23='Scrum Teams'!H$2:H$1010) + (B23='Scrum Teams'!I$2:I$1010) + (B23='Scrum Teams'!J$2:J$1010) + (B23='Scrum Teams'!K$2:K$1010) + (B23='Scrum Teams'!L$2:L$1010) + (B23='Scrum Teams'!M$2:M$1010) + (B23='Scrum Teams'!N$2:N$1010) + (B23='Scrum Teams'!O$2:O$1010) + (B23='Scrum Teams'!P$2:P$1010) + (B23='Scrum Teams'!Q$2:Q$1010), 0) ), "Not found" )} -> Compliance | P23: APLT | Q23: Rahul Rathore | R23: Core-Compliance
A24: ApplicationPlatforms | B24: AP-Printers_ Scanners | C24: Priyansu Singh | E24: Vaibhav Saini | F24: Surya Narayanan | G24: Keith Wiseman | H24: Lohit Reddy | I24: Vamsee Krishna Mullapudi | J24: Vamsee Krishna Mullapudi | K24: Vijayakumar B | M24: Shiva Somasundaram | N24: Shashi Kumar | O24: {=IFERROR( INDEX('Scrum Teams'!B$2:B$1010, MATCH(1, (B24='Scrum Teams'!F$2:F$1010) + (B24='Scrum Teams'!G$2:G$1010) + (B24='Scrum Teams'!H$2:H$1010) + (B24='Scrum Teams'!I$2:I$1010) + (B24='Scrum Teams'!J$2:J$1010) + (B24='Scrum Teams'!K$2:K$1010) + (B24='Scrum Teams'!L$2:L$1010) + (B24='Scrum Teams'!M$2:M$1010) + (B24='Scrum Teams'!N$2:N$1010) + (B24='Scrum Teams'!O$2:O$1010) + (B24='Scrum Teams'!P$2:P$1010) + (B24='Scrum Teams'!Q$2:Q$1010), 0) ), "Not found" )} -> Not found | P24: APLT | Q24: Rahul Rathore | R24: Core-PrinterScanner
A25: ApplicationPlatforms | B25: AP-Enterprise | C25: Aditya Pandey | E25: Vaibhav Saini | F25: Surya Narayanan | G25: Keith Wiseman | H25: Sudeep Kapadia | K25: Vijayakumar B | M25: Shiva Somasundaram | N25: Shashi Kumar | O25: {=IFERROR( INDEX('Scrum Teams'!B$2:B$1010, MATCH(1, (B25='Scrum Teams'!F$2:F$1010) + (B25='Scrum Teams'!G$2:G$1010) + (B25='Scrum Teams'!H$2:H$1010) + (B25='Scrum Teams'!I$2:I$1010) + (B25='Scrum Teams'!J$2:J$1010) + (B25='Scrum Teams'!K$2:K$1010) + (B25='Scrum Teams'!L$2:L$1010) + (B25='Scrum Teams'!M$2:M$1010) + (B25='Scrum Teams'!N$2:N$1010) + (B25='Scrum Teams'!O$2:O$1010) + (B25='Scrum Teams'!P$2:P$1010) + (B25='Scrum Teams'!Q$2:Q$1010), 0) ), "Not found" )} -> Enterprise | P25: APLT | Q25: Rahul Rathore | R25: Core-Foundation
A26: ApplicationPlatforms | B26: AP-Config_Studio | C26: Priyansu Singh | E26: Vaibhav Saini | F26: Surya Narayanan | G26: Keith Wiseman | H26: Anshika Chaturvedi | I26: Vamsee Krishna Mullapudi | J26: Vamsee Krishna Mullapudi | K26: Vijayakumar B | M26: Shiva Somasundaram | N26: Shashi Kumar | O26: {=IFERROR( INDEX('Scrum Teams'!B$2:B$1010, MATCH(1, (B26='Scrum Teams'!F$2:F$1010) + (B26='Scrum Teams'!G$2:G$1010) + (B26='Scrum Teams'!H$2:H$1010) + (B26='Scrum Teams'!I$2:I$1010) + (B26='Scrum Teams'!J$2:J$1010) + (B26='Scrum Teams'!K$2:K$1010) + (B26='Scrum Teams'!L$2:L$1010) + (B26='Scrum Teams'!M$2:M$1010) + (B26='Scrum Teams'!N$2:N$1010) + (B26='Scrum Teams'!O$2:O$1010) + (B26='Scrum Teams'!P$2:P$1010) + (B26='Scrum Teams'!Q$2:Q$1010), 0) ), "Not found" )} -> Configuration Studio | P26: APLT | Q26: Rahul Rathore | R26: Core-DealerConfigurations
A27: ApplicationPlatforms | B27: AP-Workflow_Engine | C27: Priyansu Singh | E27: Vaibhav Saini | F27: Surya Narayanan | G27: Keith Wiseman | H27: Jaideep Gangwar | I27: Subhash Mohan | K27: Rashmi Prakash | L27: Gaurav Gupta | M27: Satyavrat Mudgil | N27: Shashi Kumar | O27: {=IFERROR( INDEX('Scrum Teams'!B$2:B$1010, MATCH(1, (B27='Scrum Teams'!F$2:F$1010) + (B27='Scrum Teams'!G$2:G$1010) + (B27='Scrum Teams'!H$2:H$1010) + (B27='Scrum Teams'!I$2:I$1010) + (B27='Scrum Teams'!J$2:J$1010) + (B27='Scrum Teams'!K$2:K$1010) + (B27='Scrum Teams'!L$2:L$1010) + (B27='Scrum Teams'!M$2:M$1010) + (B27='Scrum Teams'!N$2:N$1010) + (B27='Scrum Teams'!O$2:O$1010) + (B27='Scrum Teams'!P$2:P$1010) + (B27='Scrum Teams'!Q$2:Q$1010), 0) ), "Not found" )} -> Workflow Engine | P27: APLT | Q27: Rahul Rathore | R27: Core-RuleEngine
A28: ApplicationPlatforms | B28: AP-Identity_Mgt | C28: Venkatesh naik | E28: Vaibhav Saini | F28: Surya Narayanan | G28: Keith Wiseman | H28: Jayashri Soundararajan | I28: Vamsee Krishna Mullapudi | J28: Vamsee Krishna Mullapudi | K28: Vijayakumar B | M28: Shiva Somasundaram | N28: Shashi Kumar | O28: {=IFERROR( INDEX('Scrum Teams'!B$2:B$1010, MATCH(1, (B28='Scrum Teams'!F$2:F$1010) + (B28='Scrum Teams'!G$2:G$1010) + (B28='Scrum Teams'!H$2:H$1010) + (B28='Scrum Teams'!I$2:I$1010) + (B28='Scrum Teams'!J$2:J$1010) + (B28='Scrum Teams'!K$2:K$1010) + (B28='Scrum Teams'!L$2:L$1010) + (B28='Scrum Teams'!M$2:M$1010) + (B28='Scrum Teams'!N$2:N$1010) + (B28='Scrum Teams'!O$2:O$1010) + (B28='Scrum Teams'!P$2:P$1010) + (B28='Scrum Teams'!Q$2:Q$1010), 0) ), "Not found" )} -> Identity Management | P28: APLT | Q28: Rahul Rathore | R28: Core-IdentityManagement
A29: ApplicationPlatforms | B29: AP-Audit_Approval | C29: Aditya Pandey | E29: Vaibhav Saini | F29: Surya Narayanan | G29: Keith Wiseman | H29: Sudeep Kapadia | K29: Vijayakumar B | M29: Shiva Somasundaram | N29: Shashi Kumar | O29: {=IFERROR( INDEX('Scrum Teams'!B$2:B$1010, MATCH(1, (B29='Scrum Teams'!F$2:F$1010) + (B29='Scrum Teams'!G$2:G$1010) + (B29='Scrum Teams'!H$2:H$1010) + (B29='Scrum Teams'!I$2:I$1010) + (B29='Scrum Teams'!J$2:J$1010) + (B29='Scrum Teams'!K$2:K$1010) + (B29='Scrum Teams'!L$2:L$1010) + (B29='Scrum Teams'!M$2:M$1010) + (B29='Scrum Teams'!N$2:N$1010) + (B29='Scrum Teams'!O$2:O$1010) + (B29='Scrum Teams'!P$2:P$1010) + (B29='Scrum Teams'!Q$2:Q$1010), 0) ), "Not found" )} -> Audit & Approval | P29: APLT | Q29: Rahul Rathore
A30: ZEBRA | B30: ZEBRA-Bootstrapping | C30: Shivam Goyal | E30: Bobby Alexander | F30: Surya Narayanan | G30: Keith Wiseman | H30: No PM Coverage | I30: No PM Coverage | J30: No PM Coverage | K30: No PM Coverage | L30: No PM Coverage | M30: Shiva Somasundaram | O30: {=IFERROR( INDEX('Scrum Teams'!B$2:B$1010, MATCH(1, (B30='Scrum Teams'!F$2:F$1010) + (B30='Scrum Teams'!G$2:G$1010) + (B30='Scrum Teams'!H$2:H$1010) + (B30='Scrum Teams'!I$2:I$1010) + (B30='Scrum Teams'!J$2:J$1010) + (B30='Scrum Teams'!K$2:K$1010) + (B30='Scrum Teams'!L$2:L$1010) + (B30='Scrum Teams'!M$2:M$1010) + (B30='Scrum Teams'!N$2:N$1010) + (B30='Scrum Teams'!O$2:O$1010) + (B30='Scrum Teams'!P$2:P$1010) + (B30='Scrum Teams'!Q$2:Q$1010), 0) ), "Not found" )} -> Zebra | P30: ZEB | Q30: Rahul Rathore
A31: ZEBRA | B31: ZEBRA-GoLiveSupport | C31: Shivam Goyal | E31: Bobby Alexander | F31: Surya Narayanan | G31: Keith Wiseman | H31: No PM Coverage | I31: No PM Coverage | J31: No PM Coverage | K31: No PM Coverage | L31: No PM Coverage | M31: Shiva Somasundaram | O31: {=IFERROR( INDEX('Scrum Teams'!B$2:B$1010, MATCH(1, (B31='Scrum Teams'!F$2:F$1010) + (B31='Scrum Teams'!G$2:G$1010) + (B31='Scrum Teams'!H$2:H$1010) + (B31='Scrum Teams'!I$2:I$1010) + (B31='Scrum Teams'!J$2:J$1010) + (B31='Scrum Teams'!K$2:K$1010) + (B31='Scrum Teams'!L$2:L$1010) + (B31='Scrum Teams'!M$2:M$1010) + (B31='Scrum Teams'!N$2:N$1010) + (B31='Scrum Teams'!O$2:O$1010) + (B31='Scrum Teams'!P$2:P$1010) + (B31='Scrum Teams'!Q$2:Q$1010), 0) ), "Not found" )} -> Zebra | P31: ZEB | Q31: Rahul Rathore
A32: ZEBRA | B32: ZEBRA-InternalTools | C32: Shivam Goyal | E32: Bobby Alexander | F32: Surya Narayanan | G32: Keith Wiseman | H32: No PM Coverage | I32: No PM Coverage | J32: No PM Coverage | K32: No PM Coverage | L32: No PM Coverage | M32: Shiva Somasundaram | O32: {=IFERROR( INDEX('Scrum Teams'!B$2:B$1010, MATCH(1, (B32='Scrum Teams'!F$2:F$1010) + (B32='Scrum Teams'!G$2:G$1010) + (B32='Scrum Teams'!H$2:H$1010) + (B32='Scrum Teams'!I$2:I$1010) + (B32='Scrum Teams'!J$2:J$1010) + (B32='Scrum Teams'!K$2:K$1010) + (B32='Scrum Teams'!L$2:L$1010) + (B32='Scrum Teams'!M$2:M$1010) + (B32='Scrum Teams'!N$2:N$1010) + (B32='Scrum Teams'!O$2:O$1010) + (B32='Scrum Teams'!P$2:P$1010) + (B32='Scrum Teams'!Q$2:Q$1010), 0) ), "Not found" )} -> Not found | P32: ZEB | Q32: Rahul Rathore | R32: Core-InternalTools
A33: ARCIntegration | B33: ARCIntegration-Accounting | C33: Raghavendra Pai | E33: Prakash Mohan | F33: Prakash Mohan | G33: Turker Coskun | H33: Bismah Kiani | I33: Hanuth Singh | J33: Hanuth Singh | M33: Satyavrat Mudgil | N33: Abhinandan Srinivas | O33: {=IFERROR( INDEX('Scrum Teams'!B$2:B$1010, MATCH(1, (B33='Scrum Teams'!F$2:F$1010) + (B33='Scrum Teams'!G$2:G$1010) + (B33='Scrum Teams'!H$2:H$1010) + (B33='Scrum Teams'!I$2:I$1010) + (B33='Scrum Teams'!J$2:J$1010) + (B33='Scrum Teams'!K$2:K$1010) + (B33='Scrum Teams'!L$2:L$1010) + (B33='Scrum Teams'!M$2:M$1010) + (B33='Scrum Teams'!N$2:N$1010) + (B33='Scrum Teams'!O$2:O$1010) + (B33='Scrum Teams'!P$2:P$1010) + (B33='Scrum Teams'!Q$2:Q$1010), 0) ), "Not found" )} -> Credit & FNI Integrations | P33: INTG | Q33: Nishanth Nag
A34: ARCIntegration | B34: ARCIntegration-Core | C34: Raghavendra Pai | E34: Prakash Mohan | F34: Prakash Mohan | G34: Turker Coskun | H34: No PM Coverage | K34: Tom Jude Ammanthurutil | M34: Turker Coskun | N34: Abhinandan Srinivas | O34: {=IFERROR( INDEX('Scrum Teams'!B$2:B$1010, MATCH(1, (B34='Scrum Teams'!F$2:F$1010) + (B34='Scrum Teams'!G$2:G$1010) + (B34='Scrum Teams'!H$2:H$1010) + (B34='Scrum Teams'!I$2:I$1010) + (B34='Scrum Teams'!J$2:J$1010) + (B34='Scrum Teams'!K$2:K$1010) + (B34='Scrum Teams'!L$2:L$1010) + (B34='Scrum Teams'!M$2:M$1010) + (B34='Scrum Teams'!N$2:N$1010) + (B34='Scrum Teams'!O$2:O$1010) + (B34='Scrum Teams'!P$2:P$1010) + (B34='Scrum Teams'!Q$2:Q$1010), 0) ), "Not found" )} -> Credit & FNI Integrations | P34: INTG | Q34: Nishanth Nag
A35: ARCIntegration | B35: ARCIntegration-CreditApp&eContracting | C35: Raghavendra Pai | E35: Prakash Mohan | F35: Prakash Mohan | G35: Turker Coskun | H35: Mudra Surana | I35: Saurabh Birla | J35: Saurabh Birla | K35: Irfan Presswala | L35: Irfan Presswala | M35: Satyavrat Mudgil | N35: Abhinandan Srinivas | O35: {=IFERROR( INDEX('Scrum Teams'!B$2:B$1010, MATCH(1, (B35='Scrum Teams'!F$2:F$1010) + (B35='Scrum Teams'!G$2:G$1010) + (B35='Scrum Teams'!H$2:H$1010) + (B35='Scrum Teams'!I$2:I$1010) + (B35='Scrum Teams'!J$2:J$1010) + (B35='Scrum Teams'!K$2:K$1010) + (B35='Scrum Teams'!L$2:L$1010) + (B35='Scrum Teams'!M$2:M$1010) + (B35='Scrum Teams'!N$2:N$1010) + (B35='Scrum Teams'!O$2:O$1010) + (B35='Scrum Teams'!P$2:P$1010) + (B35='Scrum Teams'!Q$2:Q$1010), 0) ), "Not found" )} -> Credit & FNI Integrations | P35: INTG | Q35: Nishanth Nag
A36: ARCIntegration | B36: ARCIntegration-CRM | C36: Raghavendra Pai | E36: Prakash Mohan | F36: Prakash Mohan | G36: Turker Coskun | H36: Siddharth Bountra | K36: Tom Jude Ammanthurutil | M36: Turker Coskun | N36: Abhinandan Srinivas | O36: {=IFERROR( INDEX('Scrum Teams'!B$2:B$1010, MATCH(1, (B36='Scrum Teams'!F$2:F$1010) + (B36='Scrum Teams'!G$2:G$1010) + (B36='Scrum Teams'!H$2:H$1010) + (B36='Scrum Teams'!I$2:I$1010) + (B36='Scrum Teams'!J$2:J$1010) + (B36='Scrum Teams'!K$2:K$1010) + (B36='Scrum Teams'!L$2:L$1010) + (B36='Scrum Teams'!M$2:M$1010) + (B36='Scrum Teams'!N$2:N$1010) + (B36='Scrum Teams'!O$2:O$1010) + (B36='Scrum Teams'!P$2:P$1010) + (B36='Scrum Teams'!Q$2:Q$1010), 0) ), "Not found" )} -> Retail Integration 2 | P36: INTG | Q36: Nishanth Nag
A37: ARCIntegration | B37: ARCIntegration-DRS | C37: Raghavendra Pai | E37: Prakash Mohan | F37: Prakash Mohan | G37: Turker Coskun | H37: Ankush Kedia | K37: Suraj Jain | L37: Gaurav Gupta | M37: Satyavrat Mudgil | N37: Abhinandan Srinivas | O37: {=IFERROR( INDEX('Scrum Teams'!B$2:B$1010, MATCH(1, (B37='Scrum Teams'!F$2:F$1010) + (B37='Scrum Teams'!G$2:G$1010) + (B37='Scrum Teams'!H$2:H$1010) + (B37='Scrum Teams'!I$2:I$1010) + (B37='Scrum Teams'!J$2:J$1010) + (B37='Scrum Teams'!K$2:K$1010) + (B37='Scrum Teams'!L$2:L$1010) + (B37='Scrum Teams'!M$2:M$1010) + (B37='Scrum Teams'!N$2:N$1010) + (B37='Scrum Teams'!O$2:O$1010) + (B37='Scrum Teams'!P$2:P$1010) + (B37='Scrum Teams'!Q$2:Q$1010), 0) ), "Not found" )} -> Retail Integration 2 | P37: INTG | Q37: Nishanth Nag
A38: ARCIntegration | B38: ARCIntegration-F&I | C38: Raghavendra Pai | E38: Prakash Mohan | F38: Prakash Mohan | G38: Turker Coskun | H38: Prakhar Gaur | I38: Saurabh Birla | J38: Saurabh Birla | K38: Irfan Presswala | L38: Irfan Presswala | M38: Satyavrat Mudgil | N38: Abhinandan Srinivas | O38: {=IFERROR( INDEX('Scrum Teams'!B$2:B$1010, MATCH(1, (B38='Scrum Teams'!F$2:F$1010) + (B38='Scrum Teams'!G$2:G$1010) + (B38='Scrum Teams'!H$2:H$1010) + (B38='Scrum Teams'!I$2:I$1010) + (B38='Scrum Teams'!J$2:J$1010) + (B38='Scrum Teams'!K$2:K$1010) + (B38='Scrum Teams'!L$2:L$1010) + (B38='Scrum Teams'!M$2:M$1010) + (B38='Scrum Teams'!N$2:N$1010) + (B38='Scrum Teams'!O$2:O$1010) + (B38='Scrum Teams'!P$2:P$1010) + (B38='Scrum Teams'!Q$2:Q$1010), 0) ), "Not found" )} -> Credit & FNI Integrations | P38: INTG | Q38: Nishanth Nag
A39: ARCIntegration | B39: ARCIntegration-Parts | C39: D M Raj Karthick | D39: D M Raj Karthick | E39: Prakash Mohan | F39: Prakash Mohan | G39: Turker Coskun | H39: Uday Wadhera | I39: Arjun Rajeev | K39: Tom Jude Ammanthurutil | M39: Turker Coskun | N39: Abhinandan Srinivas | O39: {=IFERROR( INDEX('Scrum Teams'!B$2:B$1010, MATCH(1, (B39='Scrum Teams'!F$2:F$1010) + (B39='Scrum Teams'!G$2:G$1010) + (B39='Scrum Teams'!H$2:H$1010) + (B39='Scrum Teams'!I$2:I$1010) + (B39='Scrum Teams'!J$2:J$1010) + (B39='Scrum Teams'!K$2:K$1010) + (B39='Scrum Teams'!L$2:L$1010) + (B39='Scrum Teams'!M$2:M$1010) + (B39='Scrum Teams'!N$2:N$1010) + (B39='Scrum Teams'!O$2:O$1010) + (B39='Scrum Teams'!P$2:P$1010) + (B39='Scrum Teams'!Q$2:Q$1010), 0) ), "Not found" )} -> FixedOps Integration 3 | P39: INTG | Q39: Nishanth Nag
A40: ARCIntegration | B40: ARCIntegration-Platform | C40: D M Raj Karthick | D40: D M Raj Karthick | E40: Prakash Mohan | F40: Prakash Mohan | G40: Turker Coskun | H40: Advait Anand | I40: Dhanapal Mohanaswamy | K40: Tom Jude Ammanthurutil | M40: Turker Coskun | N40: Abhinandan Srinivas | O40: {=IFERROR( INDEX('Scrum Teams'!B$2:B$1010, MATCH(1, (B40='Scrum Teams'!F$2:F$1010) + (B40='Scrum Teams'!G$2:G$1010) + (B40='Scrum Teams'!H$2:H$1010) + (B40='Scrum Teams'!I$2:I$1010) + (B40='Scrum Teams'!J$2:J$1010) + (B40='Scrum Teams'!K$2:K$1010) + (B40='Scrum Teams'!L$2:L$1010) + (B40='Scrum Teams'!M$2:M$1010) + (B40='Scrum Teams'!N$2:N$1010) + (B40='Scrum Teams'!O$2:O$1010) + (B40='Scrum Teams'!P$2:P$1010) + (B40='Scrum Teams'!Q$2:Q$1010), 0) ), "Not found" )} -> Platform Integrations | P40: INTG | Q40: Nishanth Nag
...

Sheet Capacity
A1: Project / Space | B1: Key | C1: Past Velocity | D1: Sprint Capacity | E1: Monthly Capacity for Calc | F1: Discrepancy? | G1: Component | H1: Key | I1: Sprint Capacity | J1: Monthly Capacity for Calc | K1: Discrepancy? | L1: Component | M1: Scrum Team | N1: Key | O1: Sprint Capacity | P1: Actual Monthly Capacity | Q1: Monthly Capacity for Calc | R1: VP | T1: Teams | U1: May-25 | V1: Jun-25 | W1: Jul-25 | X1: Velocity
A2: Accounting | B2: ACCT | D2: =IF(E2="","",E2/2) -> 285 | E2: =IF(B2="","",SUMIFS($J$2:$J$39,$H$2:$H$39,B2)) -> 570 | F2: {=IF(B2="","",_xlfn.LET( _xlpm.comp, TRIM(CLEAN(B2)), _xlpm.expected, E2, _xlpm.actual, SUMPRODUCT(--(TRIM(CLEAN($H$2:$H$140))=_xlpm.comp), $J$2:$J$140), IF(_xlpm.actual=_xlpm.expected, "No", "Mismatch by " & (_xlpm.actual-_xlpm.expected)) ))} -> No | G2: {=IFERROR(INDEX(_xlfn._xlws.SORT(_xlfn.UNIQUE(_xlfn._xlws.FILTER($L$2:$L$140,$L$2:$L$140<>""))),ROW()-1),"")} -> Accounting | H2: =IF(G2="", "", _xlfn.XLOOKUP(G2, 'Component Masterlist v2'!A:A, 'Component Masterlist v2'!P:P, "Not found")) -> ACCT | I2: =IF(J2="","",J2/2) -> 285 | J2: =IF(G2="","",SUMIFS($Q$2:$Q$140,$L$2:$L$140,G2)) -> 570 | K2: {=IF(G2="","",_xlfn.LET( _xlpm.comp, TRIM(CLEAN(G2)), _xlpm.expected, J2, _xlpm.actual, SUMPRODUCT(--(TRIM(CLEAN($L$2:$L$140))=_xlpm.comp), $Q$2:$Q$140), IF(_xlpm.actual=_xlpm.expected, "No", "Mismatch by " & (_xlpm.actual-_xlpm.expected)) ))} -> No | L2: =IF(M2="", "", _xlfn.XLOOKUP(M2,'Scrum Teams'!B:B,'Scrum Teams'!A:A,"")) -> Accounting | M2: {=IFERROR(INDEX(_xlfn.SORTBY(_xlfn.UNIQUE(_xlfn._xlws.FILTER('Scrum Teams'!$B$2:$B$1006,'Scrum Teams'!$B$2:$B$1006<>"")),_xlfn.XLOOKUP(_xlfn.UNIQUE(_xlfn._xlws.FILTER('Scrum Teams'!$B$2:$B$1006,'Scrum Teams'!$B$2:$B$1006<>"")),'Scrum Teams'!$B:$B,'Scrum Teams'!$A:$A,"")),ROW()-1),"")} -> Gold | N2: =IF(L2="", "", _xlfn.XLOOKUP(L2, 'Component Masterlist v2'!A:A, 'Component Masterlist v2'!P:P, "Not found")) -> ACCT | O2: =IF(P2="", "", P2/2) -> 86 | P2: =IF(M2="","",_xlfn.LET( _xlpm.pos, MATCH(M2,'Scrum Teams'!$B$2:$B$1006,0), _xlpm.val, INDEX('Scrum Teams'!$E$2:$E$1006,_xlpm.pos), IF(ISBLANK(INDEX('Scrum Teams'!$E$2:$E$1006,_xlpm.pos)),"",_xlpm.val) )) -> 172 | Q2: =IF(L2="","",IF(P2<>"", P2, 90)) -> 172 | R2: =IF(M2="","",IF(L2="", "Missing component", _xlfn.XLOOKUP(L2, Lookup!A:A, Lookup!D:D, "NA"))) -> Sanyam Agrawal | S2: Refresh? | T2: Platform | U2: 139.5 | V2: 124 | W2: 182.5 | X2: 148.66667
A3: AEPlatform | B3: AEP | D3: =IF(E3="","",E3/2) -> 765 | E3: =IF(B3="","",SUMIFS($J$2:$J$39,$H$2:$H$39,B3)) -> 1530 | F3: {=IF(B3="","",_xlfn.LET( _xlpm.comp, TRIM(CLEAN(B3)), _xlpm.expected, E3, _xlpm.actual, SUMPRODUCT(--(TRIM(CLEAN($H$2:$H$140))=_xlpm.comp), $J$2:$J$140), IF(_xlpm.actual=_xlpm.expected, "No", "Mismatch by " & (_xlpm.actual-_xlpm.expected)) ))} -> No | G3: {=IFERROR(INDEX(_xlfn._xlws.SORT(_xlfn.UNIQUE(_xlfn._xlws.FILTER($L$2:$L$140,$L$2:$L$140<>""))),ROW()-1),"")} -> AEPlatform | H3: =IF(G3="", "", _xlfn.XLOOKUP(G3, 'Component Masterlist v2'!A:A, 'Component Masterlist v2'!P:P, "Not found")) -> AEP | I3: =IF(J3="","",J3/2) -> 765 | J3: =IF(G3="","",SUMIFS($Q$2:$Q$140,$L$2:$L$140,G3)) -> 1530 | K3: {=IF(G3="","",_xlfn.LET( _xlpm.comp, TRIM(CLEAN(G3)), _xlpm.expected, J3, _xlpm.actual, SUMPRODUCT(--(TRIM(CLEAN($L$2:$L$140))=_xlpm.comp), $Q$2:$Q$140), IF(_xlpm.actual=_xlpm.expected, "No", "Mismatch by " & (_xlpm.actual-_xlpm.expected)) ))} -> No | L3: =IF(M3="", "", _xlfn.XLOOKUP(M3,'Scrum Teams'!B:B,'Scrum Teams'!A:A,"")) -> Accounting | M3: {=IFERROR(INDEX(_xlfn.SORTBY(_xlfn.UNIQUE(_xlfn._xlws.FILTER('Scrum Teams'!$B$2:$B$1006,'Scrum Teams'!$B$2:$B$1006<>"")),_xlfn.XLOOKUP(_xlfn.UNIQUE(_xlfn._xlws.FILTER('Scrum Teams'!$B$2:$B$1006,'Scrum Teams'!$B$2:$B$1006<>"")),'Scrum Teams'!$B:$B,'Scrum Teams'!$A:$A,"")),ROW()-1),"")} -> Helium | N3: =IF(L3="", "", _xlfn.XLOOKUP(L3, 'Component Masterlist v2'!A:A, 'Component Masterlist v2'!P:P, "Not found")) -> ACCT | O3: =IF(P3="", "", P3/2) -> 58 | P3: =IF(M3="","",_xlfn.LET( _xlpm.pos, MATCH(M3,'Scrum Teams'!$B$2:$B$1006,0), _xlpm.val, INDEX('Scrum Teams'!$E$2:$E$1006,_xlpm.pos), IF(ISBLANK(INDEX('Scrum Teams'!$E$2:$E$1006,_xlpm.pos)),"",_xlpm.val) )) -> 116 | Q3: =IF(L3="","",IF(P3<>"", P3, 90)) -> 116 | R3: =IF(M3="","",IF(L3="", "Missing component", _xlfn.XLOOKUP(L3, Lookup!A:A, Lookup!D:D, "NA"))) -> Sanyam Agrawal | S3: {=IF( SUM(--ISNA(MATCH( _xlfn.UNIQUE(_xlfn._xlws.FILTER('Scrum Teams'!B2:B1010, 'Scrum Teams'!B2:B1010<>"")), _xlfn.UNIQUE(_xlfn._xlws.FILTER(M2:M1010, M2:M1010<>"")), 0 ))) > 0, "Yes", IF( AND( COUNT(_xlfn.UNIQUE(_xlfn._xlws.FILTER(M2:M1010, M2:M1010<>""))) = COUNT(_xlfn.UNIQUE(_xlfn._xlws.FILTER('Scrum Teams'!B2:B1010, 'Scrum Teams'!B2:B1010<>""))), SUM(--ISNA(MATCH( _xlfn.UNIQUE(_xlfn._xlws.FILTER(M2:M1010, M2:M1010<>"")), _xlfn.UNIQUE(_xlfn._xlws.FILTER('Scrum Teams'!B2:B1010, 'Scrum Teams'!B2:B1010<>"")), 0 )))=0 ), "No", "Check" ) )} -> No | T3: Retail | U3: 709 | V3: 481 | W3: 399 | X3: 529.66667
A4: AI | B4: AI | D4: =IF(E4="","",E4/2) -> 150 | E4: =IF(B4="","",SUMIFS($J$2:$J$39,$H$2:$H$39,B4)) -> 300 | F4: {=IF(B4="","",_xlfn.LET( _xlpm.comp, TRIM(CLEAN(B4)), _xlpm.expected, E4, _xlpm.actual, SUMPRODUCT(--(TRIM(CLEAN($H$2:$H$140))=_xlpm.comp), $J$2:$J$140), IF(_xlpm.actual=_xlpm.expected, "No", "Mismatch by " & (_xlpm.actual-_xlpm.expected)) ))} -> No | G4: {=IFERROR(INDEX(_xlfn._xlws.SORT(_xlfn.UNIQUE(_xlfn._xlws.FILTER($L$2:$L$140,$L$2:$L$140<>""))),ROW()-1),"")} -> AI_Core | H4: =IF(G4="", "", _xlfn.XLOOKUP(G4, 'Component Masterlist v2'!A:A, 'Component Masterlist v2'!P:P, "Not found")) -> AI | I4: =IF(J4="","",J4/2) -> 150 | J4: =IF(G4="","",SUMIFS($Q$2:$Q$140,$L$2:$L$140,G4)) -> 300 | K4: {=IF(G4="","",_xlfn.LET( _xlpm.comp, TRIM(CLEAN(G4)), _xlpm.expected, J4, _xlpm.actual, SUMPRODUCT(--(TRIM(CLEAN($L$2:$L$140))=_xlpm.comp), $Q$2:$Q$140), IF(_xlpm.actual=_xlpm.expected, "No", "Mismatch by " & (_xlpm.actual-_xlpm.expected)) ))} -> No | L4: =IF(M4="", "", _xlfn.XLOOKUP(M4,'Scrum Teams'!B:B,'Scrum Teams'!A:A,"")) -> Accounting | M4: {=IFERROR(INDEX(_xlfn.SORTBY(_xlfn.UNIQUE(_xlfn._xlws.FILTER('Scrum Teams'!$B$2:$B$1006,'Scrum Teams'!$B$2:$B$1006<>"")),_xlfn.XLOOKUP(_xlfn.UNIQUE(_xlfn._xlws.FILTER('Scrum Teams'!$B$2:$B$1006,'Scrum Teams'!$B$2:$B$1006<>"")),'Scrum Teams'!$B:$B,'Scrum Teams'!$A:$A,"")),ROW()-1),"")} -> Hydrogen | N4: =IF(L4="", "", _xlfn.XLOOKUP(L4, 'Component Masterlist v2'!A:A, 'Component Masterlist v2'!P:P, "Not found")) -> ACCT | O4: =IF(P4="", "", P4/2) -> 51 | P4: =IF(M4="","",_xlfn.LET( _xlpm.pos, MATCH(M4,'Scrum Teams'!$B$2:$B$1006,0), _xlpm.val, INDEX('Scrum Teams'!$E$2:$E$1006,_xlpm.pos), IF(ISBLANK(INDEX('Scrum Teams'!$E$2:$E$1006,_xlpm.pos)),"",_xlpm.val) )) -> 102 | Q4: =IF(L4="","",IF(P4<>"", P4, 90)) -> 102 | R4: =IF(M4="","",IF(L4="", "Missing component", _xlfn.XLOOKUP(L4, Lookup!A:A, Lookup!D:D, "NA"))) -> Sanyam Agrawal
A5: AI Platform | B5: AIPL | D5: =IF(E5="","",E5/2) -> 112.5 | E5: =IF(B5="","",SUMIFS($J$2:$J$39,$H$2:$H$39,B5)) -> 225 | F5: {=IF(B5="","",_xlfn.LET( _xlpm.comp, TRIM(CLEAN(B5)), _xlpm.expected, E5, _xlpm.actual, SUMPRODUCT(--(TRIM(CLEAN($H$2:$H$140))=_xlpm.comp), $J$2:$J$140), IF(_xlpm.actual=_xlpm.expected, "No", "Mismatch by " & (_xlpm.actual-_xlpm.expected)) ))} -> No | G5: {=IFERROR(INDEX(_xlfn._xlws.SORT(_xlfn.UNIQUE(_xlfn._xlws.FILTER($L$2:$L$140,$L$2:$L$140<>""))),ROW()-1),"")} -> AIBDC | H5: =IF(G5="", "", _xlfn.XLOOKUP(G5, 'Component Masterlist v2'!A:A, 'Component Masterlist v2'!P:P, "Not found")) -> AIB | I5: =IF(J5="","",J5/2) -> 87.5 | J5: =IF(G5="","",SUMIFS($Q$2:$Q$140,$L$2:$L$140,G5)) -> 175 | K5: {=IF(G5="","",_xlfn.LET( _xlpm.comp, TRIM(CLEAN(G5)), _xlpm.expected, J5, _xlpm.actual, SUMPRODUCT(--(TRIM(CLEAN($L$2:$L$140))=_xlpm.comp), $Q$2:$Q$140), IF(_xlpm.actual=_xlpm.expected, "No", "Mismatch by " & (_xlpm.actual-_xlpm.expected)) ))} -> No | L5: =IF(M5="", "", _xlfn.XLOOKUP(M5,'Scrum Teams'!B:B,'Scrum Teams'!A:A,"")) -> Accounting | M5: {=IFERROR(INDEX(_xlfn.SORTBY(_xlfn.UNIQUE(_xlfn._xlws.FILTER('Scrum Teams'!$B$2:$B$1006,'Scrum Teams'!$B$2:$B$1006<>"")),_xlfn.XLOOKUP(_xlfn.UNIQUE(_xlfn._xlws.FILTER('Scrum Teams'!$B$2:$B$1006,'Scrum Teams'!$B$2:$B$1006<>"")),'Scrum Teams'!$B:$B,'Scrum Teams'!$A:$A,"")),ROW()-1),"")} -> Oxygen | N5: =IF(L5="", "", _xlfn.XLOOKUP(L5, 'Component Masterlist v2'!A:A, 'Component Masterlist v2'!P:P, "Not found")) -> ACCT | O5: =IF(P5="", "", P5/2) -> 18 | P5: =IF(M5="","",_xlfn.LET( _xlpm.pos, MATCH(M5,'Scrum Teams'!$B$2:$B$1006,0), _xlpm.val, INDEX('Scrum Teams'!$E$2:$E$1006,_xlpm.pos), IF(ISBLANK(INDEX('Scrum Teams'!$E$2:$E$1006,_xlpm.pos)),"",_xlpm.val) )) -> 36 | Q5: =IF(L5="","",IF(P5<>"", P5, 90)) -> 36 | R5: =IF(M5="","",IF(L5="", "Missing component", _xlfn.XLOOKUP(L5, Lookup!A:A, Lookup!D:D, "NA"))) -> Sanyam Agrawal
A6: AIBDC | B6: AIB | D6: =IF(E6="","",E6/2) -> 87.5 | E6: =IF(B6="","",SUMIFS($J$2:$J$39,$H$2:$H$39,B6)) -> 175 | F6: {=IF(B6="","",_xlfn.LET( _xlpm.comp, TRIM(CLEAN(B6)), _xlpm.expected, E6, _xlpm.actual, SUMPRODUCT(--(TRIM(CLEAN($H$2:$H$140))=_xlpm.comp), $J$2:$J$140), IF(_xlpm.actual=_xlpm.expected, "No", "Mismatch by " & (_xlpm.actual-_xlpm.expected)) ))} -> No | G6: {=IFERROR(INDEX(_xlfn._xlws.SORT(_xlfn.UNIQUE(_xlfn._xlws.FILTER($L$2:$L$140,$L$2:$L$140<>""))),ROW()-1),"")} -> AIE_Core | H6: =IF(G6="", "", _xlfn.XLOOKUP(G6, 'Component Masterlist v2'!A:A, 'Component Masterlist v2'!P:P, "Not found")) -> AIPL | I6: =IF(J6="","",J6/2) -> 67.5 | J6: =IF(G6="","",SUMIFS($Q$2:$Q$140,$L$2:$L$140,G6)) -> 135 | K6: {=IF(G6="","",_xlfn.LET( _xlpm.comp, TRIM(CLEAN(G6)), _xlpm.expected, J6, _xlpm.actual, SUMPRODUCT(--(TRIM(CLEAN($L$2:$L$140))=_xlpm.comp), $Q$2:$Q$140), IF(_xlpm.actual=_xlpm.expected, "No", "Mismatch by " & (_xlpm.actual-_xlpm.expected)) ))} -> No | L6: =IF(M6="", "", _xlfn.XLOOKUP(M6,'Scrum Teams'!B:B,'Scrum Teams'!A:A,"")) -> Accounting | M6: {=IFERROR(INDEX(_xlfn.SORTBY(_xlfn.UNIQUE(_xlfn._xlws.FILTER('Scrum Teams'!$B$2:$B$1006,'Scrum Teams'!$B$2:$B$1006<>"")),_xlfn.XLOOKUP(_xlfn.UNIQUE(_xlfn._xlws.FILTER('Scrum Teams'!$B$2:$B$1006,'Scrum Teams'!$B$2:$B$1006<>"")),'Scrum Teams'!$B:$B,'Scrum Teams'!$A:$A,"")),ROW()-1),"")} -> Platinum | N6: =IF(L6="", "", _xlfn.XLOOKUP(L6, 'Component Masterlist v2'!A:A, 'Component Masterlist v2'!P:P, "Not found")) -> ACCT | O6: =IF(P6="", "", P6/2) -> 54 | P6: =IF(M6="","",_xlfn.LET( _xlpm.pos, MATCH(M6,'Scrum Teams'!$B$2:$B$1006,0), _xlpm.val, INDEX('Scrum Teams'!$E$2:$E$1006,_xlpm.pos), IF(ISBLANK(INDEX('Scrum Teams'!$E$2:$E$1006,_xlpm.pos)),"",_xlpm.val) )) -> 108 | Q6: =IF(L6="","",IF(P6<>"", P6, 90)) -> 108 | R6: =IF(M6="","",IF(L6="", "Missing component", _xlfn.XLOOKUP(L6, Lookup!A:A, Lookup!D:D, "NA"))) -> Sanyam Agrawal
A7: Analytics | B7: ANLY | D7: =IF(E7="","",E7/2) -> 112.5 | E7: =IF(B7="","",SUMIFS($J$2:$J$39,$H$2:$H$39,B7)) -> 225 | F7: {=IF(B7="","",_xlfn.LET( _xlpm.comp, TRIM(CLEAN(B7)), _xlpm.expected, E7, _xlpm.actual, SUMPRODUCT(--(TRIM(CLEAN($H$2:$H$140))=_xlpm.comp), $J$2:$J$140), IF(_xlpm.actual=_xlpm.expected, "No", "Mismatch by " & (_xlpm.actual-_xlpm.expected)) ))} -> No | G7: {=IFERROR(INDEX(_xlfn._xlws.SORT(_xlfn.UNIQUE(_xlfn._xlws.FILTER($L$2:$L$140,$L$2:$L$140<>""))),ROW()-1),"")} -> AIE_Platform | H7: =IF(G7="", "", _xlfn.XLOOKUP(G7, 'Component Masterlist v2'!A:A, 'Component Masterlist v2'!P:P, "Not found")) -> AIPL | I7: =IF(J7="","",J7/2) -> 45 | J7: =IF(G7="","",SUMIFS($Q$2:$Q$140,$L$2:$L$140,G7)) -> 90 | K7: {=IF(G7="","",_xlfn.LET( _xlpm.comp, TRIM(CLEAN(G7)), _xlpm.expected, J7, _xlpm.actual, SUMPRODUCT(--(TRIM(CLEAN($L$2:$L$140))=_xlpm.comp), $Q$2:$Q$140), IF(_xlpm.actual=_xlpm.expected, "No", "Mismatch by " & (_xlpm.actual-_xlpm.expected)) ))} -> No | L7: =IF(M7="", "", _xlfn.XLOOKUP(M7,'Scrum Teams'!B:B,'Scrum Teams'!A:A,"")) -> Accounting | M7: {=IFERROR(INDEX(_xlfn.SORTBY(_xlfn.UNIQUE(_xlfn._xlws.FILTER('Scrum Teams'!$B$2:$B$1006,'Scrum Teams'!$B$2:$B$1006<>"")),_xlfn.XLOOKUP(_xlfn.UNIQUE(_xlfn._xlws.FILTER('Scrum Teams'!$B$2:$B$1006,'Scrum Teams'!$B$2:$B$1006<>"")),'Scrum Teams'!$B:$B,'Scrum Teams'!$A:$A,"")),ROW()-1),"")} -> Aurum | N7: =IF(L7="", "", _xlfn.XLOOKUP(L7, 'Component Masterlist v2'!A:A, 'Component Masterlist v2'!P:P, "Not found")) -> ACCT | O7: =IF(P7="", "", P7/2) -> 18 | P7: =IF(M7="","",_xlfn.LET( _xlpm.pos, MATCH(M7,'Scrum Teams'!$B$2:$B$1006,0), _xlpm.val, INDEX('Scrum Teams'!$E$2:$E$1006,_xlpm.pos), IF(ISBLANK(INDEX('Scrum Teams'!$E$2:$E$1006,_xlpm.pos)),"",_xlpm.val) )) -> 36 | Q7: =IF(L7="","",IF(P7<>"", P7, 90)) -> 36 | R7: =IF(M7="","",IF(L7="", "Missing component", _xlfn.XLOOKUP(L7, Lookup!A:A, Lookup!D:D, "NA"))) -> Sanyam Agrawal
A8: APC | B8: APC | D8: =IF(E8="","",E8/2) -> 175.5 | E8: =IF(B8="","",SUMIFS($J$2:$J$39,$H$2:$H$39,B8)) -> 351 | F8: {=IF(B8="","",_xlfn.LET( _xlpm.comp, TRIM(CLEAN(B8)), _xlpm.expected, E8, _xlpm.actual, SUMPRODUCT(--(TRIM(CLEAN($H$2:$H$140))=_xlpm.comp), $J$2:$J$140), IF(_xlpm.actual=_xlpm.expected, "No", "Mismatch by " & (_xlpm.actual-_xlpm.expected)) ))} -> No | G8: {=IFERROR(INDEX(_xlfn._xlws.SORT(_xlfn.UNIQUE(_xlfn._xlws.FILTER($L$2:$L$140,$L$2:$L$140<>""))),ROW()-1),"")} -> AMC | H8: =IF(G8="", "", _xlfn.XLOOKUP(G8, 'Component Masterlist v2'!A:A, 'Component Masterlist v2'!P:P, "Not found")) -> AMC | I8: =IF(J8="","",J8/2) -> 45 | J8: =IF(G8="","",SUMIFS($Q$2:$Q$140,$L$2:$L$140,G8)) -> 90 | K8: {=IF(G8="","",_xlfn.LET( _xlpm.comp, TRIM(CLEAN(G8)), _xlpm.expected, J8, _xlpm.actual, SUMPRODUCT(--(TRIM(CLEAN($L$2:$L$140))=_xlpm.comp), $Q$2:$Q$140), IF(_xlpm.actual=_xlpm.expected, "No", "Mismatch by " & (_xlpm.actual-_xlpm.expected)) ))} -> No | L8: =IF(M8="", "", _xlfn.XLOOKUP(M8,'Scrum Teams'!B:B,'Scrum Teams'!A:A,"")) -> AEPlatform | M8: {=IFERROR(INDEX(_xlfn.SORTBY(_xlfn.UNIQUE(_xlfn._xlws.FILTER('Scrum Teams'!$B$2:$B$1006,'Scrum Teams'!$B$2:$B$1006<>"")),_xlfn.XLOOKUP(_xlfn.UNIQUE(_xlfn._xlws.FILTER('Scrum Teams'!$B$2:$B$1006,'Scrum Teams'!$B$2:$B$1006<>"")),'Scrum Teams'!$B:$B,'Scrum Teams'!$A:$A,"")),ROW()-1),"")} -> AEP Chat | N8: =IF(L8="", "", _xlfn.XLOOKUP(L8, 'Component Masterlist v2'!A:A, 'Component Masterlist v2'!P:P, "Not found")) -> AEP | O8: =IF(P8="", "", P8/2) -> 30 | P8: =IF(M8="","",_xlfn.LET( _xlpm.pos, MATCH(M8,'Scrum Teams'!$B$2:$B$1006,0), _xlpm.val, INDEX('Scrum Teams'!$E$2:$E$1006,_xlpm.pos), IF(ISBLANK(INDEX('Scrum Teams'!$E$2:$E$1006,_xlpm.pos)),"",_xlpm.val) )) -> 60 | Q8: =IF(L8="","",IF(P8<>"", P8, 90)) -> 60 | R8: =IF(M8="","",IF(L8="", "Missing component", _xlfn.XLOOKUP(L8, Lookup!A:A, Lookup!D:D, "NA"))) -> Santosh Golecha
A9: APEX | B9: APEX | D9: =IF(E9="","",E9/2) -> 170 | E9: =IF(B9="","",SUMIFS($J$2:$J$39,$H$2:$H$39,B9)) -> 340 | F9: {=IF(B9="","",_xlfn.LET( _xlpm.comp, TRIM(CLEAN(B9)), _xlpm.expected, E9, _xlpm.actual, SUMPRODUCT(--(TRIM(CLEAN($H$2:$H$140))=_xlpm.comp), $J$2:$J$140), IF(_xlpm.actual=_xlpm.expected, "No", "Mismatch by " & (_xlpm.actual-_xlpm.expected)) ))} -> No | G9: {=IFERROR(INDEX(_xlfn._xlws.SORT(_xlfn.UNIQUE(_xlfn._xlws.FILTER($L$2:$L$140,$L$2:$L$140<>""))),ROW()-1),"")} -> Analytics | H9: =IF(G9="", "", _xlfn.XLOOKUP(G9, 'Component Masterlist v2'!A:A, 'Component Masterlist v2'!P:P, "Not found")) -> ANLY | I9: =IF(J9="","",J9/2) -> 112.5 | J9: =IF(G9="","",SUMIFS($Q$2:$Q$140,$L$2:$L$140,G9)) -> 225 | K9: {=IF(G9="","",_xlfn.LET( _xlpm.comp, TRIM(CLEAN(G9)), _xlpm.expected, J9, _xlpm.actual, SUMPRODUCT(--(TRIM(CLEAN($L$2:$L$140))=_xlpm.comp), $Q$2:$Q$140), IF(_xlpm.actual=_xlpm.expected, "No", "Mismatch by " & (_xlpm.actual-_xlpm.expected)) ))} -> No | L9: =IF(M9="", "", _xlfn.XLOOKUP(M9,'Scrum Teams'!B:B,'Scrum Teams'!A:A,"")) -> AEPlatform | M9: {=IFERROR(INDEX(_xlfn.SORTBY(_xlfn.UNIQUE(_xlfn._xlws.FILTER('Scrum Teams'!$B$2:$B$1006,'Scrum Teams'!$B$2:$B$1006<>"")),_xlfn.XLOOKUP(_xlfn.UNIQUE(_xlfn._xlws.FILTER('Scrum Teams'!$B$2:$B$1006,'Scrum Teams'!$B$2:$B$1006<>"")),'Scrum Teams'!$B:$B,'Scrum Teams'!$A:$A,"")),ROW()-1),"")} -> AEP Checkout | N9: =IF(L9="", "", _xlfn.XLOOKUP(L9, 'Component Masterlist v2'!A:A, 'Component Masterlist v2'!P:P, "Not found")) -> AEP | O9: =IF(P9="", "", P9/2) -> 180 | P9: =IF(M9="","",_xlfn.LET( _xlpm.pos, MATCH(M9,'Scrum Teams'!$B$2:$B$1006,0), _xlpm.val, INDEX('Scrum Teams'!$E$2:$E$1006,_xlpm.pos), IF(ISBLANK(INDEX('Scrum Teams'!$E$2:$E$1006,_xlpm.pos)),"",_xlpm.val) )) -> 360 | Q9: =IF(L9="","",IF(P9<>"", P9, 90)) -> 360 | R9: =IF(M9="","",IF(L9="", "Missing component", _xlfn.XLOOKUP(L9, Lookup!A:A, Lookup!D:D, "NA"))) -> Santosh Golecha
A10: ApplicationPlatforms | B10: APLT | D10: =IF(E10="","",E10/2) -> 352 | E10: =IF(B10="","",SUMIFS($J$2:$J$39,$H$2:$H$39,B10)) -> 704 | F10: {=IF(B10="","",_xlfn.LET( _xlpm.comp, TRIM(CLEAN(B10)), _xlpm.expected, E10, _xlpm.actual, SUMPRODUCT(--(TRIM(CLEAN($H$2:$H$140))=_xlpm.comp), $J$2:$J$140), IF(_xlpm.actual=_xlpm.expected, "No", "Mismatch by " & (_xlpm.actual-_xlpm.expected)) ))} -> No | G10: {=IFERROR(INDEX(_xlfn._xlws.SORT(_xlfn.UNIQUE(_xlfn._xlws.FILTER($L$2:$L$140,$L$2:$L$140<>""))),ROW()-1),"")} -> APC | H10: =IF(G10="", "", _xlfn.XLOOKUP(G10, 'Component Masterlist v2'!A:A, 'Component Masterlist v2'!P:P, "Not found")) -> APC | I10: =IF(J10="","",J10/2) -> 175.5 | J10: =IF(G10="","",SUMIFS($Q$2:$Q$140,$L$2:$L$140,G10)) -> 351 | K10: {=IF(G10="","",_xlfn.LET( _xlpm.comp, TRIM(CLEAN(G10)), _xlpm.expected, J10, _xlpm.actual, SUMPRODUCT(--(TRIM(CLEAN($L$2:$L$140))=_xlpm.comp), $Q$2:$Q$140), IF(_xlpm.actual=_xlpm.expected, "No", "Mismatch by " & (_xlpm.actual-_xlpm.expected)) ))} -> No | L10: =IF(M10="", "", _xlfn.XLOOKUP(M10,'Scrum Teams'!B:B,'Scrum Teams'!A:A,"")) -> AEPlatform | M10: {=IFERROR(INDEX(_xlfn.SORTBY(_xlfn.UNIQUE(_xlfn._xlws.FILTER('Scrum Teams'!$B$2:$B$1006,'Scrum Teams'!$B$2:$B$1006<>"")),_xlfn.XLOOKUP(_xlfn.UNIQUE(_xlfn._xlws.FILTER('Scrum Teams'!$B$2:$B$1006,'Scrum Teams'!$B$2:$B$1006<>"")),'Scrum Teams'!$B:$B,'Scrum Teams'!$A:$A,"")),ROW()-1),"")} -> AEP Core | N10: =IF(L10="", "", _xlfn.XLOOKUP(L10, 'Component Masterlist v2'!A:A, 'Component Masterlist v2'!P:P, "Not found")) -> AEP | O10: =IF(P10="", "", P10/2) -> 90 | P10: =IF(M10="","",_xlfn.LET( _xlpm.pos, MATCH(M10,'Scrum Teams'!$B$2:$B$1006,0), _xlpm.val, INDEX('Scrum Teams'!$E$2:$E$1006,_xlpm.pos), IF(ISBLANK(INDEX('Scrum Teams'!$E$2:$E$1006,_xlpm.pos)),"",_xlpm.val) )) -> 180 | Q10: =IF(L10="","",IF(P10<>"", P10, 90)) -> 180 | R10: =IF(M10="","",IF(L10="", "Missing component", _xlfn.XLOOKUP(L10, Lookup!A:A, Lookup!D:D, "NA"))) -> Santosh Golecha
A11: Cashiering | B11: CASH | D11: =IF(E11="","",E11/2) -> 34 | E11: =IF(B11="","",SUMIFS($J$2:$J$39,$H$2:$H$39,B11)) -> 68 | F11: {=IF(B11="","",_xlfn.LET( _xlpm.comp, TRIM(CLEAN(B11)), _xlpm.expected, E11, _xlpm.actual, SUMPRODUCT(--(TRIM(CLEAN($H$2:$H$140))=_xlpm.comp), $J$2:$J$140), IF(_xlpm.actual=_xlpm.expected, "No", "Mismatch by " & (_xlpm.actual-_xlpm.expected)) ))} -> No | G11: {=IFERROR(INDEX(_xlfn._xlws.SORT(_xlfn.UNIQUE(_xlfn._xlws.FILTER($L$2:$L$140,$L$2:$L$140<>""))),ROW()-1),"")} -> APEX | H11: =IF(G11="", "", _xlfn.XLOOKUP(G11, 'Component Masterlist v2'!A:A, 'Component Masterlist v2'!P:P, "Not found")) -> APEX | I11: =IF(J11="","",J11/2) -> 170 | J11: =IF(G11="","",SUMIFS($Q$2:$Q$140,$L$2:$L$140,G11)) -> 340 | K11: {=IF(G11="","",_xlfn.LET( _xlpm.comp, TRIM(CLEAN(G11)), _xlpm.expected, J11, _xlpm.actual, SUMPRODUCT(--(TRIM(CLEAN($L$2:$L$140))=_xlpm.comp), $Q$2:$Q$140), IF(_xlpm.actual=_xlpm.expected, "No", "Mismatch by " & (_xlpm.actual-_xlpm.expected)) ))} -> No | L11: =IF(M11="", "", _xlfn.XLOOKUP(M11,'Scrum Teams'!B:B,'Scrum Teams'!A:A,"")) -> AEPlatform | M11: {=IFERROR(INDEX(_xlfn.SORTBY(_xlfn.UNIQUE(_xlfn._xlws.FILTER('Scrum Teams'!$B$2:$B$1006,'Scrum Teams'!$B$2:$B$1006<>"")),_xlfn.XLOOKUP(_xlfn.UNIQUE(_xlfn._xlws.FILTER('Scrum Teams'!$B$2:$B$1006,'Scrum Teams'!$B$2:$B$1006<>"")),'Scrum Teams'!$B:$B,'Scrum Teams'!$A:$A,"")),ROW()-1),"")} -> AEP Retail | N11: =IF(L11="", "", _xlfn.XLOOKUP(L11, 'Component Masterlist v2'!A:A, 'Component Masterlist v2'!P:P, "Not found")) -> AEP | O11: =IF(P11="", "", P11/2) -> 120 | P11: =IF(M11="","",_xlfn.LET( _xlpm.pos, MATCH(M11,'Scrum Teams'!$B$2:$B$1006,0), _xlpm.val, INDEX('Scrum Teams'!$E$2:$E$1006,_xlpm.pos), IF(ISBLANK(INDEX('Scrum Teams'!$E$2:$E$1006,_xlpm.pos)),"",_xlpm.val) )) -> 240 | Q11: =IF(L11="","",IF(P11<>"", P11, 90)) -> 240 | R11: =IF(M11="","",IF(L11="", "Missing component", _xlfn.XLOOKUP(L11, Lookup!A:A, Lookup!D:D, "NA"))) -> Santosh Golecha
A12: Communication | B12: COMM | D12: =IF(E12="","",E12/2) -> 135 | E12: =IF(B12="","",SUMIFS($J$2:$J$39,$H$2:$H$39,B12)) -> 270 | F12: {=IF(B12="","",_xlfn.LET( _xlpm.comp, TRIM(CLEAN(B12)), _xlpm.expected, E12, _xlpm.actual, SUMPRODUCT(--(TRIM(CLEAN($H$2:$H$140))=_xlpm.comp), $J$2:$J$140), IF(_xlpm.actual=_xlpm.expected, "No", "Mismatch by " & (_xlpm.actual-_xlpm.expected)) ))} -> No | G12: {=IFERROR(INDEX(_xlfn._xlws.SORT(_xlfn.UNIQUE(_xlfn._xlws.FILTER($L$2:$L$140,$L$2:$L$140<>""))),ROW()-1),"")} -> ApplicationPlatforms | H12: =IF(G12="", "", _xlfn.XLOOKUP(G12, 'Component Masterlist v2'!A:A, 'Component Masterlist v2'!P:P, "Not found")) -> APLT | I12: =IF(J12="","",J12/2) -> 352 | J12: =IF(G12="","",SUMIFS($Q$2:$Q$140,$L$2:$L$140,G12)) -> 704 | K12: {=IF(G12="","",_xlfn.LET( _xlpm.comp, TRIM(CLEAN(G12)), _xlpm.expected, J12, _xlpm.actual, SUMPRODUCT(--(TRIM(CLEAN($L$2:$L$140))=_xlpm.comp), $Q$2:$Q$140), IF(_xlpm.actual=_xlpm.expected, "No", "Mismatch by " & (_xlpm.actual-_xlpm.expected)) ))} -> No | L12: =IF(M12="", "", _xlfn.XLOOKUP(M12,'Scrum Teams'!B:B,'Scrum Teams'!A:A,"")) -> AEPlatform | M12: {=IFERROR(INDEX(_xlfn.SORTBY(_xlfn.UNIQUE(_xlfn._xlws.FILTER('Scrum Teams'!$B$2:$B$1006,'Scrum Teams'!$B$2:$B$1006<>"")),_xlfn.XLOOKUP(_xlfn.UNIQUE(_xlfn._xlws.FILTER('Scrum Teams'!$B$2:$B$1006,'Scrum Teams'!$B$2:$B$1006<>"")),'Scrum Teams'!$B:$B,'Scrum Teams'!$A:$A,"")),ROW()-1),"")} -> AEP FnI | N12: =IF(L12="", "", _xlfn.XLOOKUP(L12, 'Component Masterlist v2'!A:A, 'Component Masterlist v2'!P:P, "Not found")) -> AEP | O12: =IF(P12="", "", P12/2) -> 120 | P12: =IF(M12="","",_xlfn.LET( _xlpm.pos, MATCH(M12,'Scrum Teams'!$B$2:$B$1006,0), _xlpm.val, INDEX('Scrum Teams'!$E$2:$E$1006,_xlpm.pos), IF(ISBLANK(INDEX('Scrum Teams'!$E$2:$E$1006,_xlpm.pos)),"",_xlpm.val) )) -> 240 | Q12: =IF(L12="","",IF(P12<>"", P12, 90)) -> 240 | R12: =IF(M12="","",IF(L12="", "Missing component", _xlfn.XLOOKUP(L12, Lookup!A:A, Lookup!D:D, "NA"))) -> Santosh Golecha
